<sdf version='1.10'>
  <world name='empty'>
    <physics name='1ms' type='ignored'>
      <max_step_size>0.001</max_step_size>
      <real_time_factor>1</real_time_factor>
      <real_time_update_rate>1000</real_time_update_rate>
    </physics>
    <plugin name='gz::sim::systems::Physics' filename='gz-sim-physics-system'/>
    <plugin name='gz::sim::systems::UserCommands' filename='gz-sim-user-commands-system'/>
    <plugin name='gz::sim::systems::SceneBroadcaster' filename='gz-sim-scene-broadcaster-system'/>
    <plugin name='gz::sim::systems::Contact' filename='gz-sim-contact-system'/>
    <gravity>0 0 -9.8000000000000007</gravity>
    <magnetic_field>5.5644999999999998e-06 2.2875799999999999e-05 -4.2388400000000002e-05</magnetic_field>
    <atmosphere type='adiabatic'/>
    <scene>
      <ambient>0.400000006 0.400000006 0.400000006 1</ambient>
      <background>0.699999988 0.699999988 0.699999988 1</background>
      <shadows>true</shadows>
    </scene>
    <model name='ground_plane'>
      <static>true</static>
      <link name='link'>
        <collision name='collision'>
          <geometry>
            <plane>
              <normal>0 0 1</normal>
              <size>100 100</size>
            </plane>
          </geometry>
          <surface>
            <friction>
              <ode/>
            </friction>
            <bounce/>
            <contact/>
          </surface>
        </collision>
        <visual name='visual'>
          <geometry>
            <plane>
              <normal>0 0 1</normal>
              <size>100 100</size>
            </plane>
          </geometry>
          <material>
            <ambient>0.800000012 0.800000012 0.800000012 1</ambient>
            <diffuse>0.800000012 0.800000012 0.800000012 1</diffuse>
            <specular>0.800000012 0.800000012 0.800000012 1</specular>
          </material>
        </visual>
        <pose>0 0 0 0 0 0</pose>
        <inertial>
          <pose>0 0 0 0 0 0</pose>
          <mass>1</mass>
          <inertia>
            <ixx>1</ixx>
            <ixy>0</ixy>
            <ixz>0</ixz>
            <iyy>1</iyy>
            <iyz>0</iyz>
            <izz>1</izz>
          </inertia>
        </inertial>
        <enable_wind>false</enable_wind>
      </link>
      <pose>0 0 0 0 0 0</pose>
      <self_collide>false</self_collide>
    </model>
    <model name='my_bot'>
      <link name='base_link'>
        <inertial>
          <pose>0.0027118644067796621 0 0.055084745762711863 0 0 0</pose>
          <mass>5.9000000000000004</mass>
          <inertia>
            <ixx>0.070932457627118653</ixx>
            <ixy>0</ixy>
            <ixz>-0.001298644067796611</ixz>
            <iyy>0.075049067796610178</iyy>
            <iyz>0</iyz>
            <izz>0.067116610169491525</izz>
          </inertia>
        </inertial>
        <collision name='base_link_fixed_joint_lump__chassis_collision'>
          <pose>0 0 0.040000000000000001 0 0 0</pose>
          <geometry>
            <box>
              <size>0.25 0.16 0.050000000000000003</size>
            </box>
          </geometry>
          <surface>
            <contact>
              <ode/>
            </contact>
            <friction>
              <ode/>
            </friction>
            <bounce/>
          </surface>
        </collision>
        <collision name='base_link_fixed_joint_lump__mast_collision_1'>
          <pose>0.14000000000000001 0 0.14000000000000001 0 0 0</pose>
          <geometry>
            <box>
              <size>0.014999999999999999 0.040000000000000001 0.20000000000000001</size>
            </box>
          </geometry>
          <surface>
            <contact>
              <ode/>
            </contact>
            <friction>
              <ode/>
            </friction>
            <bounce/>
          </surface>
        </collision>
        <collision name='base_link_fixed_joint_lump__top_deck_collision_2'>
          <pose>0 0 0.10000000000000001 0 0 0</pose>
          <geometry>
            <box>
              <size>0.25 0.16 0.0050000000000000001</size>
            </box>
          </geometry>
          <surface>
            <contact>
              <ode/>
            </contact>
            <friction>
              <ode/>
            </friction>
            <bounce/>
          </surface>
        </collision>
        <collision name='base_link_fixed_joint_lump__white_box_collision_3'>
          <pose>-0.02 0 0.13500000000000001 0 0 0</pose>
          <geometry>
            <box>
              <size>0.12 0.10000000000000001 0.070000000000000007</size>
            </box>
          </geometry>
          <surface>
            <contact>
              <ode/>
            </contact>
            <friction>
              <ode/>
            </friction>
            <bounce/>
          </surface>
        </collision>
        <collision name='base_link_fixed_joint_lump__laser_frame_collision_4'>
          <pose>-0.02 0 0.19500000000000001 0 0 0</pose>
          <geometry>
            <cylinder>
              <length>0.02</length>
              <radius>0.035000000000000003</radius>
            </cylinder>
          </geometry>
          <surface>
            <contact>
              <ode/>
            </contact>
            <friction>
              <ode/>
            </friction>
            <bounce/>
          </surface>
        </collision>
        <visual name='base_link_fixed_joint_lump__chassis_visual'>
          <pose>0 0 0.040000000000000001 0 0 0</pose>
          <geometry>
            <box>
              <size>0.25 0.16 0.01</size>
            </box>
          </geometry>
          <material>
            <script>
              <name>Gazebo/FlatBlack</name>
              <uri>file://media/materials/scripts/gazebo.material</uri>
            </script>
            <diffuse>0.125 0.125 0.125 1</diffuse>
            <ambient>0.125 0.125 0.125 1</ambient>
          </material>
        </visual>
        <visual name='base_link_fixed_joint_lump__mast_visual_1'>
          <pose>0.14000000000000001 0 0.14000000000000001 0 0 0</pose>
          <geometry>
            <box>
              <size>0.014999999999999999 0.040000000000000001 0.20000000000000001</size>
            </box>
          </geometry>
          <material>
            <script>
              <name>Gazebo/Grey</name>
              <uri>file://media/materials/scripts/gazebo.material</uri>
            </script>
            <diffuse>1 1 1 1</diffuse>
            <ambient>1 1 1 1</ambient>
          </material>
        </visual>
        <visual name='base_link_fixed_joint_lump__camera_link_visual_2'>
          <pose>0.14999999999999999 0 0.23999999999999999 0 0 0</pose>
          <geometry>
            <box>
              <size>0.02 0.040000000000000001 0.02</size>
            </box>
          </geometry>
          <material>
            <diffuse>0.125 0.125 0.125 1</diffuse>
            <ambient>0.125 0.125 0.125 1</ambient>
          </material>
        </visual>
        <visual name='base_link_fixed_joint_lump__pillar_-0.11_-0.07_visual_3'>
          <pose>-0.11 -0.070000000000000007 0.070000000000000007 0 0 0</pose>
          <geometry>
            <cylinder>
              <length>0.059999999999999998</length>
              <radius>0.0030000000000000001</radius>
            </cylinder>
          </geometry>
          <material>
            <script>
              <name>Gazebo/Gold</name>
              <uri>file://media/materials/scripts/gazebo.material</uri>
            </script>
            <diffuse>1 0.75000006 0.25 1</diffuse>
            <ambient>1 0.75000006 0.25 1</ambient>
          </material>
        </visual>
        <visual name='base_link_fixed_joint_lump__pillar_-0.11_0.07_visual_4'>
          <pose>-0.11 0.070000000000000007 0.070000000000000007 0 0 0</pose>
          <geometry>
            <cylinder>
              <length>0.059999999999999998</length>
              <radius>0.0030000000000000001</radius>
            </cylinder>
          </geometry>
          <material>
            <script>
              <name>Gazebo/Gold</name>
              <uri>file://media/materials/scripts/gazebo.material</uri>
            </script>
            <diffuse>1 0.75000006 0.25 1</diffuse>
            <ambient>1 0.75000006 0.25 1</ambient>
          </material>
        </visual>
        <visual name='base_link_fixed_joint_lump__pillar_0.11_-0.07_visual_5'>
          <pose>0.11 -0.070000000000000007 0.070000000000000007 0 0 0</pose>
          <geometry>
            <cylinder>
              <length>0.059999999999999998</length>
              <radius>0.0030000000000000001</radius>
            </cylinder>
          </geometry>
          <material>
            <script>
              <name>Gazebo/Gold</name>
              <uri>file://media/materials/scripts/gazebo.material</uri>
            </script>
            <diffuse>1 0.75000006 0.25 1</diffuse>
            <ambient>1 0.75000006 0.25 1</ambient>
          </material>
        </visual>
        <visual name='base_link_fixed_joint_lump__pillar_0.11_0.07_visual_6'>
          <pose>0.11 0.070000000000000007 0.070000000000000007 0 0 0</pose>
          <geometry>
            <cylinder>
              <length>0.059999999999999998</length>
              <radius>0.0030000000000000001</radius>
            </cylinder>
          </geometry>
          <material>
            <script>
              <name>Gazebo/Gold</name>
              <uri>file://media/materials/scripts/gazebo.material</uri>
            </script>
            <diffuse>1 0.75000006 0.25 1</diffuse>
            <ambient>1 0.75000006 0.25 1</ambient>
          </material>
        </visual>
        <visual name='base_link_fixed_joint_lump__top_deck_visual_7'>
          <pose>0 0 0.10000000000000001 0 0 0</pose>
          <geometry>
            <box>
              <size>0.25 0.16 0.0050000000000000001</size>
            </box>
          </geometry>
          <material>
            <script>
              <name>Gazebo/FlatBlack</name>
              <uri>file://media/materials/scripts/gazebo.material</uri>
            </script>
            <diffuse>0.125 0.125 0.125 1</diffuse>
            <ambient>0.125 0.125 0.125 1</ambient>
          </material>
        </visual>
        <visual name='base_link_fixed_joint_lump__white_box_visual_8'>
          <pose>-0.02 0 0.13500000000000001 0 0 0</pose>
          <geometry>
            <box>
              <size>0.12 0.10000000000000001 0.070000000000000007</size>
            </box>
          </geometry>
          <material>
            <script>
              <name>Gazebo/White</name>
              <uri>file://media/materials/scripts/gazebo.material</uri>
            </script>
            <diffuse>1 1 1 1</diffuse>
            <ambient>1 1 1 1</ambient>
          </material>
        </visual>
        <visual name='base_link_fixed_joint_lump__laser_frame_visual_9'>
          <pose>-0.02 0 0.19500000000000001 0 0 0</pose>
          <geometry>
            <cylinder>
              <length>0.02</length>
              <radius>0.035000000000000003</radius>
            </cylinder>
          </geometry>
          <material>
            <diffuse>0.125 0.125 0.125 1</diffuse>
            <ambient>0.125 0.125 0.125 1</ambient>
          </material>
        </visual>
        <sensor name='lidar' type='gpu_lidar'>
          <pose>-0.02 0 0.19500000000000001 0 0 0</pose>
          <topic>scan</topic>
          <update_rate>10</update_rate>
          <enable_metrics>false</enable_metrics>
          <lidar>
            <scan>
              <horizontal>
                <samples>500</samples>
                <resolution>1</resolution>
                <min_angle>-3.1415899999999999</min_angle>
                <max_angle>3.1415899999999999</max_angle>
              </horizontal>
              <vertical>
                <samples>1</samples>
                <min_angle>0</min_angle>
                <max_angle>0</max_angle>
                <resolution>1</resolution>
              </vertical>
            </scan>
            <range>
              <min>0.12</min>
              <max>10</max>
              <resolution>0.014999999999999999</resolution>
            </range>
            <noise>
              <type>gaussian</type>
              <mean>0</mean>
              <stddev>0.01</stddev>
            </noise>
            <visibility_mask>4294967295</visibility_mask>
          </lidar>
        </sensor>
        <pose>0 0 0 0 0 0</pose>
        <enable_wind>false</enable_wind>
      </link>
      <joint name='lift_joint' type='prismatic'>
        <pose>0 0 0 0 0 0</pose>
        <parent>base_link</parent>
        <child>lift_plate</child>
        <axis>
          <xyz>0 0 1</xyz>
          <limit>
            <lower>0</lower>
            <upper>0.12</upper>
            <effort>500</effort>
            <velocity>0.20000000000000001</velocity>
            <stiffness>100000000</stiffness>
            <dissipation>1</dissipation>
          </limit>
          <dynamics>
            <spring_reference>0</spring_reference>
            <spring_stiffness>0</spring_stiffness>
            <damping>0</damping>
            <friction>0</friction>
          </dynamics>
        </axis>
      </joint>
      <link name='lift_plate'>
        <pose>0.16 1.0339757656912846e-25 0.039999999999989787 0 3.9220971412536972e-23 0</pose>
        <inertial>
          <pose>0 0 0 0 0 0</pose>
          <mass>0.10000000000000001</mass>
          <inertia>
            <ixx>0.001</ixx>
            <ixy>0</ixy>
            <ixz>0</ixz>
            <iyy>0.001</iyy>
            <iyz>0</iyz>
            <izz>0.001</izz>
          </inertia>
        </inertial>
        <collision name='lift_plate_collision'>
          <pose>0 0 0 0 0 0</pose>
          <geometry>
            <box>
              <size>0.01 0.10000000000000001 0.059999999999999998</size>
            </box>
          </geometry>
          <surface>
            <friction>
              <ode/>
            </friction>
            <bounce/>
            <contact/>
          </surface>
        </collision>
        <collision name='lift_plate_fixed_joint_lump__fork_left_collision_1'>
          <pose>0.080000000000000002 0.035000000000000003 -0.02 0 0 0</pose>
          <geometry>
            <box>
              <size>0.16 0.014999999999999999 0.0050000000000000001</size>
            </box>
          </geometry>
          <surface>
            <friction>
              <ode/>
            </friction>
            <bounce/>
            <contact/>
          </surface>
        </collision>
        <collision name='lift_plate_fixed_joint_lump__fork_right_collision_2'>
          <pose>0.080000000000000002 -0.035000000000000003 -0.02 0 0 0</pose>
          <geometry>
            <box>
              <size>0.16 0.014999999999999999 0.0050000000000000001</size>
            </box>
          </geometry>
          <surface>
            <friction>
              <ode/>
            </friction>
            <bounce/>
            <contact/>
          </surface>
        </collision>
        <visual name='lift_plate_visual'>
          <pose>0 0 0 0 0 0</pose>
          <geometry>
            <box>
              <size>0.01 0.10000000000000001 0.059999999999999998</size>
            </box>
          </geometry>
          <material>
            <diffuse>0.125 0.125 0.125 1</diffuse>
            <ambient>0.125 0.125 0.125 1</ambient>
          </material>
        </visual>
        <visual name='lift_plate_fixed_joint_lump__fork_left_visual_1'>
          <pose>0.080000000000000002 0.035000000000000003 -0.02 0 0 0</pose>
          <geometry>
            <box>
              <size>0.16 0.014999999999999999 0.0050000000000000001</size>
            </box>
          </geometry>
          <material>
            <diffuse>1 0.125 0.125 1</diffuse>
            <ambient>1 0.125 0.125 1</ambient>
          </material>
        </visual>
        <visual name='lift_plate_fixed_joint_lump__fork_right_visual_2'>
          <pose>0.080000000000000002 -0.035000000000000003 -0.02 0 0 0</pose>
          <geometry>
            <box>
              <size>0.16 0.014999999999999999 0.0050000000000000001</size>
            </box>
          </geometry>
          <material>
            <diffuse>1 0.125 0.125 1</diffuse>
            <ambient>1 0.125 0.125 1</ambient>
          </material>
        </visual>
        <enable_wind>false</enable_wind>
      </link>
      <joint name='front_left_wheel_joint' type='revolute'>
        <pose>1.3877787807814457e-17 -1.3877787807814457e-17 0 0 0 0</pose>
        <parent>base_link</parent>
        <child>front_left_wheel</child>
        <axis>
          <xyz>0 0 1</xyz>
          <limit>
            <lower>-inf</lower>
            <upper>inf</upper>
            <effort>inf</effort>
            <velocity>inf</velocity>
            <stiffness>100000000</stiffness>
            <dissipation>1</dissipation>
          </limit>
          <dynamics>
            <spring_reference>0</spring_reference>
            <spring_stiffness>0</spring_stiffness>
            <damping>0</damping>
            <friction>0</friction>
          </dynamics>
        </axis>
      </joint>
      <link name='front_left_wheel'>
        <pose>0.080000000000000002 0.105 0.039999999999999994 -1.5708000000000317 -0.00013074258406485932 4.8024432982954252e-10</pose>
        <inertial>
          <pose>0 0 0 0 0 0</pose>
          <mass>0.40000000000000002</mass>
          <inertia>
            <ixx>0.001</ixx>
            <ixy>0</ixy>
            <ixz>0</ixz>
            <iyy>0.001</iyy>
            <iyz>0</iyz>
            <izz>0.001</izz>
          </inertia>
        </inertial>
        <collision name='front_left_wheel_collision'>
          <pose>0 0 0 0 0 0</pose>
          <geometry>
            <cylinder>
              <length>0.035000000000000003</length>
              <radius>0.040000000000000001</radius>
            </cylinder>
          </geometry>
          <surface>
            <contact>
              <ode/>
            </contact>
            <friction>
              <ode>
                <mu>0.01</mu>
                <mu2>0.01</mu2>
              </ode>
            </friction>
            <bounce/>
          </surface>
        </collision>
        <visual name='front_left_wheel_visual'>
          <pose>0 0 0 0 0 0</pose>
          <geometry>
            <cylinder>
              <length>0.035000000000000003</length>
              <radius>0.040000000000000001</radius>
            </cylinder>
          </geometry>
          <material>
            <script>
              <name>Gazebo/Yellow</name>
              <uri>file://media/materials/scripts/gazebo.material</uri>
            </script>
            <diffuse>1 0.9375 0 1</diffuse>
            <ambient>1 0.9375 0 1</ambient>
          </material>
        </visual>
        <enable_wind>false</enable_wind>
      </link>
      <joint name='front_right_wheel_joint' type='revolute'>
        <pose>1.3877787807814457e-17 1.3877787807814457e-17 0 0 0 0</pose>
        <parent>base_link</parent>
        <child>front_right_wheel</child>
        <axis>
          <xyz>0 0 1</xyz>
          <limit>
            <lower>-inf</lower>
            <upper>inf</upper>
            <effort>inf</effort>
            <velocity>inf</velocity>
            <stiffness>100000000</stiffness>
            <dissipation>1</dissipation>
          </limit>
          <dynamics>
            <spring_reference>0</spring_reference>
            <spring_stiffness>0</spring_stiffness>
            <damping>0</damping>
            <friction>0</friction>
          </dynamics>
        </axis>
      </joint>
      <link name='front_right_wheel'>
        <pose>0.079999999999999988 -0.105 0.040000000000000001 -1.5708000000000319 -0.00013076258905268367 4.8031781224353087e-10</pose>
        <inertial>
          <pose>0 0 0 0 0 0</pose>
          <mass>0.40000000000000002</mass>
          <inertia>
            <ixx>0.001</ixx>
            <ixy>0</ixy>
            <ixz>0</ixz>
            <iyy>0.001</iyy>
            <iyz>0</iyz>
            <izz>0.001</izz>
          </inertia>
        </inertial>
        <collision name='front_right_wheel_collision'>
          <pose>0 0 0 0 0 0</pose>
          <geometry>
            <cylinder>
              <length>0.035000000000000003</length>
              <radius>0.040000000000000001</radius>
            </cylinder>
          </geometry>
          <surface>
            <contact>
              <ode/>
            </contact>
            <friction>
              <ode>
                <mu>0.01</mu>
                <mu2>0.01</mu2>
              </ode>
            </friction>
            <bounce/>
          </surface>
        </collision>
        <visual name='front_right_wheel_visual'>
          <pose>0 0 0 0 0 0</pose>
          <geometry>
            <cylinder>
              <length>0.035000000000000003</length>
              <radius>0.040000000000000001</radius>
            </cylinder>
          </geometry>
          <material>
            <script>
              <name>Gazebo/Yellow</name>
              <uri>file://media/materials/scripts/gazebo.material</uri>
            </script>
            <diffuse>1 0.9375 0 1</diffuse>
            <ambient>1 0.9375 0 1</ambient>
          </material>
        </visual>
        <enable_wind>false</enable_wind>
      </link>
      <joint name='rear_left_wheel_joint' type='revolute'>
        <pose>-1.3877787807814457e-17 -1.3877787807814457e-17 0 0 0 0</pose>
        <parent>base_link</parent>
        <child>rear_left_wheel</child>
        <axis>
          <xyz>0 0 1</xyz>
          <limit>
            <lower>-inf</lower>
            <upper>inf</upper>
            <effort>inf</effort>
            <velocity>inf</velocity>
            <stiffness>100000000</stiffness>
            <dissipation>1</dissipation>
          </limit>
          <dynamics>
            <spring_reference>0</spring_reference>
            <spring_stiffness>0</spring_stiffness>
            <damping>0</damping>
            <friction>0</friction>
          </dynamics>
        </axis>
      </joint>
      <link name='rear_left_wheel'>
        <pose>-0.079999994607566127 0.1049999999994793 0.040000478619379984 -1.5707999999869524 1.3480760236941315e-07 3.0814559665766226e-16</pose>
        <inertial>
          <pose>0 0 0 0 0 0</pose>
          <mass>0.40000000000000002</mass>
          <inertia>
            <ixx>0.001</ixx>
            <ixy>0</ixy>
            <ixz>0</ixz>
            <iyy>0.001</iyy>
            <iyz>0</iyz>
            <izz>0.001</izz>
          </inertia>
        </inertial>
        <collision name='rear_left_wheel_collision'>
          <pose>0 0 0 0 0 0</pose>
          <geometry>
            <cylinder>
              <length>0.035000000000000003</length>
              <radius>0.040000000000000001</radius>
            </cylinder>
          </geometry>
          <surface>
            <contact>
              <ode/>
            </contact>
            <friction>
              <ode/>
            </friction>
            <bounce/>
          </surface>
        </collision>
        <visual name='rear_left_wheel_visual'>
          <pose>0 0 0 0 0 0</pose>
          <geometry>
            <cylinder>
              <length>0.035000000000000003</length>
              <radius>0.040000000000000001</radius>
            </cylinder>
          </geometry>
          <material>
            <script>
              <name>Gazebo/Yellow</name>
              <uri>file://media/materials/scripts/gazebo.material</uri>
            </script>
            <diffuse>1 0.9375 0 1</diffuse>
            <ambient>1 0.9375 0 1</ambient>
          </material>
        </visual>
        <enable_wind>false</enable_wind>
      </link>
      <joint name='rear_right_wheel_joint' type='revolute'>
        <pose>-1.3877787807814457e-17 1.3877787807814457e-17 0 0 0 0</pose>
        <parent>base_link</parent>
        <child>rear_right_wheel</child>
        <axis>
          <xyz>0 0 1</xyz>
          <limit>
            <lower>-inf</lower>
            <upper>inf</upper>
            <effort>inf</effort>
            <velocity>inf</velocity>
            <stiffness>100000000</stiffness>
            <dissipation>1</dissipation>
          </limit>
          <dynamics>
            <spring_reference>0</spring_reference>
            <spring_stiffness>0</spring_stiffness>
            <damping>0</damping>
            <friction>0</friction>
          </dynamics>
        </axis>
      </joint>
      <link name='rear_right_wheel'>
        <pose>-0.079999994607566058 -0.10500000000052069 0.040000478616639863 -1.5707999999869524 1.3480761307304251e-07 3.0810627580006393e-16</pose>
        <inertial>
          <pose>0 0 0 0 0 0</pose>
          <mass>0.40000000000000002</mass>
          <inertia>
            <ixx>0.001</ixx>
            <ixy>0</ixy>
            <ixz>0</ixz>
            <iyy>0.001</iyy>
            <iyz>0</iyz>
            <izz>0.001</izz>
          </inertia>
        </inertial>
        <collision name='rear_right_wheel_collision'>
          <pose>0 0 0 0 0 0</pose>
          <geometry>
            <cylinder>
              <length>0.035000000000000003</length>
              <radius>0.040000000000000001</radius>
            </cylinder>
          </geometry>
          <surface>
            <contact>
              <ode/>
            </contact>
            <friction>
              <ode/>
            </friction>
            <bounce/>
          </surface>
        </collision>
        <visual name='rear_right_wheel_visual'>
          <pose>0 0 0 0 0 0</pose>
          <geometry>
            <cylinder>
              <length>0.035000000000000003</length>
              <radius>0.040000000000000001</radius>
            </cylinder>
          </geometry>
          <material>
            <script>
              <name>Gazebo/Yellow</name>
              <uri>file://media/materials/scripts/gazebo.material</uri>
            </script>
            <diffuse>1 0.9375 0 1</diffuse>
            <ambient>1 0.9375 0 1</ambient>
          </material>
        </visual>
        <enable_wind>false</enable_wind>
      </link>
      <plugin name='gz::sim::systems::Sensors' filename='gz-sim-sensors-system'>
        <render_engine>ogre2</render_engine>
      </plugin>
      <plugin name='gz::sim::systems::DiffDrive' filename='gz-sim-diff-drive-system'>
        <left_joint>rear_left_wheel_joint</left_joint>
        <right_joint>rear_right_wheel_joint</right_joint>
        <wheel_separation>0.21</wheel_separation>
        <wheel_radius>0.04</wheel_radius>
        <odom_publish_frequency>50</odom_publish_frequency>
        <topic>cmd_vel</topic>
        <odom_topic>odom</odom_topic>
        <frame_id>odom</frame_id>
        <child_frame_id>base_link</child_frame_id>
        <publish_odom_tf>true</publish_odom_tf>
        <publish_wheel_tf>true</publish_wheel_tf>
      </plugin>
      <plugin name='gz::sim::systems::JointStatePublisher' filename='gz-sim-joint-state-publisher-system'/>
      <frame name='camera_joint' attached_to='mast'>
        <pose>0.01 0 0.10000000000000001 0 0 0</pose>
      </frame>
      <frame name='camera_link' attached_to='camera_joint'>
        <pose>0 0 0 0 0 0</pose>
      </frame>
      <frame name='mast_joint' attached_to='chassis'>
        <pose>0.14000000000000001 0 0.10000000000000001 0 0 0</pose>
      </frame>
      <frame name='mast' attached_to='mast_joint'>
        <pose>0 0 0 0 0 0</pose>
      </frame>
      <frame name='fork_left_joint' attached_to='lift_plate'>
        <pose>0.080000000000000002 0.035000000000000003 -0.02 0 0 0</pose>
      </frame>
      <frame name='fork_left' attached_to='fork_left_joint'>
        <pose>0 0 0 0 0 0</pose>
      </frame>
      <frame name='fork_right_joint' attached_to='lift_plate'>
        <pose>0.080000000000000002 -0.035000000000000003 -0.02 0 0 0</pose>
      </frame>
      <frame name='fork_right' attached_to='fork_right_joint'>
        <pose>0 0 0 0 0 0</pose>
      </frame>
      <frame name='standoff_-0.11_-0.07' attached_to='chassis'>
        <pose>-0.11 -0.070000000000000007 0.029999999999999999 0 0 0</pose>
      </frame>
      <frame name='pillar_-0.11_-0.07' attached_to='standoff_-0.11_-0.07'>
        <pose>0 0 0 0 0 0</pose>
      </frame>
      <frame name='standoff_-0.11_0.07' attached_to='chassis'>
        <pose>-0.11 0.070000000000000007 0.029999999999999999 0 0 0</pose>
      </frame>
      <frame name='pillar_-0.11_0.07' attached_to='standoff_-0.11_0.07'>
        <pose>0 0 0 0 0 0</pose>
      </frame>
      <frame name='standoff_0.11_-0.07' attached_to='chassis'>
        <pose>0.11 -0.070000000000000007 0.029999999999999999 0 0 0</pose>
      </frame>
      <frame name='pillar_0.11_-0.07' attached_to='standoff_0.11_-0.07'>
        <pose>0 0 0 0 0 0</pose>
      </frame>
      <frame name='standoff_0.11_0.07' attached_to='chassis'>
        <pose>0.11 0.070000000000000007 0.029999999999999999 0 0 0</pose>
      </frame>
      <frame name='pillar_0.11_0.07' attached_to='standoff_0.11_0.07'>
        <pose>0 0 0 0 0 0</pose>
      </frame>
      <frame name='laser_joint' attached_to='white_box'>
        <pose>0 0 0.059999999999999998 0 0 0</pose>
      </frame>
      <frame name='laser_frame' attached_to='laser_joint'>
        <pose>0 0 0 0 0 0</pose>
      </frame>
      <frame name='box_joint' attached_to='top_deck'>
        <pose>-0.02 0 0.035000000000000003 0 0 0</pose>
      </frame>
      <frame name='white_box' attached_to='box_joint'>
        <pose>0 0 0 0 0 0</pose>
      </frame>
      <frame name='top_deck_joint' attached_to='chassis'>
        <pose>0 0 0.059999999999999998 0 0 0</pose>
      </frame>
      <frame name='top_deck' attached_to='top_deck_joint'>
        <pose>0 0 0 0 0 0</pose>
      </frame>
      <frame name='chassis_joint' attached_to='base_link'>
        <pose>0 0 0.040000000000000001 0 0 0</pose>
      </frame>
      <frame name='chassis' attached_to='chassis_joint'>
        <pose>0 0 0 0 0 0</pose>
      </frame>
      <pose>-3.980357281481232e-06 1.1085737320309858e-10 -7.8854234354022016e-07 2.7218858980090912e-09 -2.4098060455172116e-07 -1.3513477003833587e-09</pose>
      <static>false</static>
      <self_collide>false</self_collide>
    </model>
    <model name='aws_robomaker_warehouse_WallB_01'>
      <link name='link'>
        <collision name='collision'>
          <geometry>
            <mesh>
              <uri>file:///home/ksy/.gz/fuel/fuel.gazebosim.org/openrobotics/models/aws_robomaker_warehouse_wallb_01/4/meshes/aws_robomaker_warehouse_WallB_01_collision.DAE</uri>
            </mesh>
          </geometry>
          <surface>
            <friction>
              <ode>
                <mu>0.5</mu>
                <mu2>0.5</mu2>
                <fdir1>0 0 0</fdir1>
                <slip1>0</slip1>
                <slip2>0</slip2>
              </ode>
            </friction>
          </surface>
        </collision>
        <visual name='visual'>
          <geometry>
            <mesh>
              <uri>file:///home/ksy/.gz/fuel/fuel.gazebosim.org/openrobotics/models/aws_robomaker_warehouse_wallb_01/4/meshes/aws_robomaker_warehouse_WallB_01_visual.DAE</uri>
            </mesh>
          </geometry>
          <meta>
            <layer>2</layer>
          </meta>
        </visual>
        <pose>0 0 0 0 0 0</pose>
        <inertial>
          <pose>0 0 0 0 0 0</pose>
          <mass>1</mass>
          <inertia>
            <ixx>1</ixx>
            <ixy>0</ixy>
            <ixz>0</ixz>
            <iyy>1</iyy>
            <iyz>0</iyz>
            <izz>1</izz>
          </inertia>
        </inertial>
        <enable_wind>false</enable_wind>
      </link>
      <static>true</static>
      <pose>1.5829809699437609 0.076417402619124719 0 0 0 0</pose>
      <self_collide>false</self_collide>
    </model>
    <model name='aws_robomaker_warehouse_Bucket_01'>
      <link name='body'>
        <pose>0 0 0 0 0 0</pose>
        <self_collide>false</self_collide>
        <kinematic>false</kinematic>
        <gravity>true</gravity>
        <visual name='visual'>
          <geometry>
            <mesh>
              <uri>file:///home/ksy/.gz/fuel/fuel.gazebosim.org/openrobotics/models/aws_robomaker_warehouse_bucket_01/3/meshes/aws_robomaker_warehouse_Bucket_01_visual.DAE</uri>
            </mesh>
          </geometry>
          <meta>
            <layer>1</layer>
          </meta>
        </visual>
        <collision name='collision_0'>
          <laser_retro>0</laser_retro>
          <max_contacts>10</max_contacts>
          <pose>0 0 0 0 0 0</pose>
          <geometry>
            <mesh>
              <uri>file:///home/ksy/.gz/fuel/fuel.gazebosim.org/openrobotics/models/aws_robomaker_warehouse_bucket_01/3/meshes/aws_robomaker_warehouse_Bucket_01_collision.DAE</uri>
              <scale>1 1 1</scale>
            </mesh>
          </geometry>
          <surface>
            <friction>
              <ode>
                <mu>0.40000000000000002</mu>
                <mu2>0.40000000000000002</mu2>
                <fdir1>0 0 0</fdir1>
                <slip1>0</slip1>
                <slip2>0</slip2>
              </ode>
              <torsional>
                <coefficient>1</coefficient>
                <patch_radius>0</patch_radius>
                <surface_radius>0</surface_radius>
                <use_patch_radius>true</use_patch_radius>
                <ode>
                  <slip>0</slip>
                </ode>
              </torsional>
            </friction>
          </surface>
        </collision>
        <inertial>
          <pose>0 0 0 0 0 0</pose>
          <mass>1</mass>
          <inertia>
            <ixx>1</ixx>
            <ixy>0</ixy>
            <ixz>0</ixz>
            <iyy>1</iyy>
            <iyz>0</iyz>
            <izz>1</izz>
          </inertia>
        </inertial>
        <enable_wind>false</enable_wind>
      </link>
      <static>true</static>
      <pose>7.7858099937438965 -8.7772674560546875 0 0 0 0</pose>
      <self_collide>false</self_collide>
    </model>
    <model name='aws_robomaker_warehouse_TrashCanC_01'>
      <link name='link'>
        <collision name='collision'>
          <geometry>
            <mesh>
              <uri>file:///home/ksy/.gz/fuel/fuel.gazebosim.org/openrobotics/models/aws_robomaker_warehouse_trashcanc_01/4/meshes/aws_robomaker_warehouse_TrashCanC_01_collision.DAE</uri>
            </mesh>
          </geometry>
          <surface>
            <friction>
              <ode>
                <mu>0.40000000000000002</mu>
                <mu2>0.40000000000000002</mu2>
                <fdir1>0 0 0</fdir1>
                <slip1>0</slip1>
                <slip2>0</slip2>
              </ode>
            </friction>
          </surface>
        </collision>
        <visual name='visual'>
          <geometry>
            <mesh>
              <uri>file:///home/ksy/.gz/fuel/fuel.gazebosim.org/openrobotics/models/aws_robomaker_warehouse_trashcanc_01/4/meshes/aws_robomaker_warehouse_TrashCanC_01_visual.DAE</uri>
            </mesh>
          </geometry>
          <meta>
            <layer>1</layer>
          </meta>
        </visual>
        <pose>0 0 0 0 0 0</pose>
        <inertial>
          <pose>0 0 0 0 0 0</pose>
          <mass>1</mass>
          <inertia>
            <ixx>1</ixx>
            <ixy>0</ixy>
            <ixz>0</ixz>
            <iyy>1</iyy>
            <iyz>0</iyz>
            <izz>1</izz>
          </inertia>
        </inertial>
        <enable_wind>false</enable_wind>
      </link>
      <static>true</static>
      <pose>7.350546528809458 9.5830196589260943 0 0 0 0</pose>
      <self_collide>false</self_collide>
    </model>
    <model name='aws_robomaker_warehouse_ShelfF_01'>
      <link name='link'>
        <collision name='collision'>
          <geometry>
            <mesh>
              <uri>file:///home/ksy/.gz/fuel/fuel.gazebosim.org/openrobotics/models/aws_robomaker_warehouse_shelff_01/4/meshes/aws_robomaker_warehouse_ShelfF_01_collision.DAE</uri>
            </mesh>
          </geometry>
          <surface>
            <friction>
              <ode>
                <mu>0.20000000000000001</mu>
                <mu2>0.20000000000000001</mu2>
                <fdir1>0 0 0</fdir1>
                <slip1>0</slip1>
                <slip2>0</slip2>
              </ode>
            </friction>
          </surface>
        </collision>
        <visual name='visual'>
          <geometry>
            <mesh>
              <uri>file:///home/ksy/.gz/fuel/fuel.gazebosim.org/openrobotics/models/aws_robomaker_warehouse_shelff_01/4/meshes/aws_robomaker_warehouse_ShelfF_01_visual.DAE</uri>
            </mesh>
          </geometry>
          <meta>
            <layer>1</layer>
          </meta>
        </visual>
        <pose>0 0 0 0 0 0</pose>
        <inertial>
          <pose>0 0 0 0 0 0</pose>
          <mass>1</mass>
          <inertia>
            <ixx>1</ixx>
            <ixy>0</ixy>
            <ixz>0</ixz>
            <iyy>1</iyy>
            <iyz>0</iyz>
            <izz>1</izz>
          </inertia>
        </inertial>
        <enable_wind>false</enable_wind>
      </link>
      <static>true</static>
      <pose>-4.2133040428161621 -0.97136497497558594 0 0 0 0</pose>
      <self_collide>false</self_collide>
    </model>
    <light name='sun' type='directional'>
      <pose>0 0 10 0 0 0</pose>
      <cast_shadows>true</cast_shadows>
      <intensity>1</intensity>
      <direction>-0.5 0.10000000000000001 -0.90000000000000002</direction>
      <diffuse>0.800000012 0.800000012 0.800000012 1</diffuse>
      <specular>0.200000003 0.200000003 0.200000003 1</specular>
      <attenuation>
        <range>1000</range>
        <linear>0.01</linear>
        <constant>0.90000000000000002</constant>
        <quadratic>0.001</quadratic>
      </attenuation>
      <spot>
        <inner_angle>0</inner_angle>
        <outer_angle>0</outer_angle>
        <falloff>0</falloff>
      </spot>
    </light>
  </world>
</sdf>
